Workbook
Name Segment_Province_Client: #N/A
Name Segment_Province_RDC: #N/A

Sheet Logs_Registre
A1: Source.Name | B1: Date_Heure_Panne | C1: Cell_ID | D1: Duree_Panne_Min | E1: Statut_Resolution | F1: Province_RDC | G1: Latitude | H1: longitude | I1: Technologie | J1: Equipementier | K1: Duree_Panne_Heure
A2: Logs_Reseau_Part_01.xlsx | B2: 45211.279 | C2: ANT-0001 | D2: 75 | E2: Résolu | F2: =VLOOKUP(C2,REGISTRE!B:G,2,FALSE) -> Nord-Ubangi | G2: =VLOOKUP(C2,REGISTRE!B:G,3,FALSE) -> -8.143791 | H2: =VLOOKUP(C2,REGISTRE!B:G,4,FALSE) -> 28.946161 | I2: =VLOOKUP(C2,REGISTRE!B:G,5,FALSE) -> 4G | J2: =VLOOKUP(C2,REGISTRE!B:G,6,FALSE) -> ZTE | K2: =INT(LOGS_Rx5[[#This Row],[Duree_Panne_Min]]/60) & " h " & MOD(LOGS_Rx5[[#This Row],[Duree_Panne_Min]],60) & " min " & "0 s" -> 1 h 15 min 0 s
A3: Logs_Reseau_Part_19.xlsx | B3: 45205.014 | C3: ANT-0001 | D3: 35 | E3: Non Résolu | F3: =VLOOKUP(C3,REGISTRE!B:G,2,FALSE) -> Nord-Ubangi | G3: =VLOOKUP(C3,REGISTRE!B:G,3,FALSE) -> -8.143791 | H3: =VLOOKUP(C3,REGISTRE!B:G,4,FALSE) -> 28.946161 | I3: =VLOOKUP(C3,REGISTRE!B:G,5,FALSE) -> 4G | J3: =VLOOKUP(C3,REGISTRE!B:G,6,FALSE) -> ZTE | K3: =INT(LOGS_Rx5[[#This Row],[Duree_Panne_Min]]/60) & " h " & MOD(LOGS_Rx5[[#This Row],[Duree_Panne_Min]],60) & " min " & "0 s" -> 0 h 35 min 0 s
A4: Logs_Reseau_Part_23.xlsx | B4: 45203.517 | C4: ANT-0001 | D4: 26 | E4: Résolu | F4: =VLOOKUP(C4,REGISTRE!B:G,2,FALSE) -> Nord-Ubangi | G4: =VLOOKUP(C4,REGISTRE!B:G,3,FALSE) -> -8.143791 | H4: =VLOOKUP(C4,REGISTRE!B:G,4,FALSE) -> 28.946161 | I4: =VLOOKUP(C4,REGISTRE!B:G,5,FALSE) -> 4G | J4: =VLOOKUP(C4,REGISTRE!B:G,6,FALSE) -> ZTE | K4: =INT(LOGS_Rx5[[#This Row],[Duree_Panne_Min]]/60) & " h " & MOD(LOGS_Rx5[[#This Row],[Duree_Panne_Min]],60) & " min " & "0 s" -> 0 h 26 min 0 s
A5: Logs_Reseau_Part_05.xlsx | B5: 45224.568 | C5: ANT-0002 | D5: 27 | E5: Résolu | F5: =VLOOKUP(C5,REGISTRE!B:G,2,FALSE) -> Mai-Ndombe | G5: =VLOOKUP(C5,REGISTRE!B:G,3,FALSE) -> -10.442425 | H5: =VLOOKUP(C5,REGISTRE!B:G,4,FALSE) -> 23.243632 | I5: =VLOOKUP(C5,REGISTRE!B:G,5,FALSE) -> 4G | J5: =VLOOKUP(C5,REGISTRE!B:G,6,FALSE) -> Nokia | K5: =INT(LOGS_Rx5[[#This Row],[Duree_Panne_Min]]/60) & " h " & MOD(LOGS_Rx5[[#This Row],[Duree_Panne_Min]],60) & " min " & "0 s" -> 0 h 27 min 0 s
A6: Logs_Reseau_Part_12.xlsx | B6: 45230.868 | C6: ANT-0006 | D6: 103 | E6: En Cours | F6: =VLOOKUP(C6,REGISTRE!B:G,2,FALSE) -> Bas-Uele | G6: =VLOOKUP(C6,REGISTRE!B:G,3,FALSE) -> -2.853287 | H6: =VLOOKUP(C6,REGISTRE!B:G,4,FALSE) -> 22.117896 | I6: =VLOOKUP(C6,REGISTRE!B:G,5,FALSE) -> 5G | J6: =VLOOKUP(C6,REGISTRE!B:G,6,FALSE) -> Huawei | K6: =INT(LOGS_Rx5[[#This Row],[Duree_Panne_Min]]/60) & " h " & MOD(LOGS_Rx5[[#This Row],[Duree_Panne_Min]],60) & " min " & "0 s" -> 1 h 43 min 0 s
A7: Logs_Reseau_Part_24.xlsx | B7: 45230.429 | C7: ANT-0006 | D7: 11 | E7: En Cours | F7: =VLOOKUP(C7,REGISTRE!B:G,2,FALSE) -> Bas-Uele | G7: =VLOOKUP(C7,REGISTRE!B:G,3,FALSE) -> -2.853287 | H7: =VLOOKUP(C7,REGISTRE!B:G,4,FALSE) -> 22.117896 | I7: =VLOOKUP(C7,REGISTRE!B:G,5,FALSE) -> 5G | J7: =VLOOKUP(C7,REGISTRE!B:G,6,FALSE) -> Huawei | K7: =INT(LOGS_Rx5[[#This Row],[Duree_Panne_Min]]/60) & " h " & MOD(LOGS_Rx5[[#This Row],[Duree_Panne_Min]],60) & " min " & "0 s" -> 0 h 11 min 0 s
A8: Logs_Reseau_Part_14.xlsx | B8: 45221.566 | C8: ANT-0007 | D8: 87 | E8: Non Résolu | F8: =VLOOKUP(C8,REGISTRE!B:G,2,FALSE) -> Tshopo | G8: =VLOOKUP(C8,REGISTRE!B:G,3,FALSE) -> 4.777735 | H8: =VLOOKUP(C8,REGISTRE!B:G,4,FALSE) -> 16.392204 | I8: =VLOOKUP(C8,REGISTRE!B:G,5,FALSE) -> 5G | J8: =VLOOKUP(C8,REGISTRE!B:G,6,FALSE) -> ZTE | K8: =INT(LOGS_Rx5[[#This Row],[Duree_Panne_Min]]/60) & " h " & MOD(LOGS_Rx5[[#This Row],[Duree_Panne_Min]],60) & " min " & "0 s" -> 1 h 27 min 0 s
A9: Logs_Reseau_Part_21.xlsx | B9: 45222.501 | C9: ANT-0008 | D9: 39 | E9: Résolu | F9: =VLOOKUP(C9,REGISTRE!B:G,2,FALSE) -> Haut-Lomami | G9: =VLOOKUP(C9,REGISTRE!B:G,3,FALSE) -> -11.89448 | H9: =VLOOKUP(C9,REGISTRE!B:G,4,FALSE) -> 19.216215 | I9: =VLOOKUP(C9,REGISTRE!B:G,5,FALSE) -> 3G | J9: =VLOOKUP(C9,REGISTRE!B:G,6,FALSE) -> ZTE | K9: =INT(LOGS_Rx5[[#This Row],[Duree_Panne_Min]]/60) & " h " & MOD(LOGS_Rx5[[#This Row],[Duree_Panne_Min]],60) & " min " & "0 s" -> 0 h 39 min 0 s
A10: Logs_Reseau_Part_02.xlsx | B10: 45223.419 | C10: ANT-0010 | D10: 89 | E10: Résolu | F10: =VLOOKUP(C10,REGISTRE!B:G,2,FALSE) -> Haut-Katanga | G10: =VLOOKUP(C10,REGISTRE!B:G,3,FALSE) -> 4.471256 | H10: =VLOOKUP(C10,REGISTRE!B:G,4,FALSE) -> 27.107028 | I10: =VLOOKUP(C10,REGISTRE!B:G,5,FALSE) -> 3G | J10: =VLOOKUP(C10,REGISTRE!B:G,6,FALSE) -> Ericsson | K10: =INT(LOGS_Rx5[[#This Row],[Duree_Panne_Min]]/60) & " h " & MOD(LOGS_Rx5[[#This Row],[Duree_Panne_Min]],60) & " min " & "0 s" -> 1 h 29 min 0 s
A11: Logs_Reseau_Part_22.xlsx | B11: 45210.835 | C11: ANT-0010 | D11: 80 | E11: Non Résolu | F11: =VLOOKUP(C11,REGISTRE!B:G,2,FALSE) -> Haut-Katanga | G11: =VLOOKUP(C11,REGISTRE!B:G,3,FALSE) -> 4.471256 | H11: =VLOOKUP(C11,REGISTRE!B:G,4,FALSE) -> 27.107028 | I11: =VLOOKUP(C11,REGISTRE!B:G,5,FALSE) -> 3G | J11: =VLOOKUP(C11,REGISTRE!B:G,6,FALSE) -> Ericsson | K11: =INT(LOGS_Rx5[[#This Row],[Duree_Panne_Min]]/60) & " h " & MOD(LOGS_Rx5[[#This Row],[Duree_Panne_Min]],60) & " min " & "0 s" -> 1 h 20 min 0 s
A12: Logs_Reseau_Part_04.xlsx | B12: 45202.852 | C12: ANT-0011 | D12: 83 | E12: Résolu | F12: =VLOOKUP(C12,REGISTRE!B:G,2,FALSE) -> Mai-Ndombe | G12: =VLOOKUP(C12,REGISTRE!B:G,3,FALSE) -> -1.607639 | H12: =VLOOKUP(C12,REGISTRE!B:G,4,FALSE) -> 17.003636 | I12: =VLOOKUP(C12,REGISTRE!B:G,5,FALSE) -> 4G | J12: =VLOOKUP(C12,REGISTRE!B:G,6,FALSE) -> Ericsson | K12: =INT(LOGS_Rx5[[#This Row],[Duree_Panne_Min]]/60) & " h " & MOD(LOGS_Rx5[[#This Row],[Duree_Panne_Min]],60) & " min " & "0 s" -> 1 h 23 min 0 s
A13: Logs_Reseau_Part_01.xlsx | B13: 45217.969 | C13: ANT-0020 | D13: 97 | E13: Non Résolu | F13: =VLOOKUP(C13,REGISTRE!B:G,2,FALSE) -> Kasaï | G13: =VLOOKUP(C13,REGISTRE!B:G,3,FALSE) -> -10.059846 | H13: =VLOOKUP(C13,REGISTRE!B:G,4,FALSE) -> 14.375758 | I13: =VLOOKUP(C13,REGISTRE!B:G,5,FALSE) -> 4G | J13: =VLOOKUP(C13,REGISTRE!B:G,6,FALSE) -> Huawei | K13: =INT(LOGS_Rx5[[#This Row],[Duree_Panne_Min]]/60) & " h " & MOD(LOGS_Rx5[[#This Row],[Duree_Panne_Min]],60) & " min " & "0 s" -> 1 h 37 min 0 s
... A548: Logs_Reseau_Part_05.xlsx | B548: 45216.73 | C548: ANT-0997 | D548: 109 | E548: En Cours | F548: =VLOOKUP(C548,REGISTRE!B:G,2,FALSE) -> Kasai-Oriental | G548: =VLOOKUP(C548,REGISTRE!B:G,3,FALSE) -> 0.639208 | H548: =VLOOKUP(C548,REGISTRE!B:G,4,FALSE) -> 20.701739 | I548: =VLOOKUP(C548,REGISTRE!B:G,5,FALSE) -> 4G | J548: =VLOOKUP(C548,REGISTRE!B:G,6,FALSE) -> Huawei | K548: =INT(LOGS_Rx5[[#This Row],[Duree_Panne_Min]]/60) & " h " & MOD(LOGS_Rx5[[#This Row],[Duree_Panne_Min]],60) & " min " & "0 s" -> 1 h 49 min 0 s

Sheet TCD_CLIENT
B8: NOMBRE DE CLIENT | D8: TYPE DE CLIENT | H8: SOMME FACTURE MENSUELLE ET REMISE | K8: SOMME FACTURE MENSUELLE PAR FORFAIT
B11: Nombre de client | D11: Type de client | E11: Nombre de client | H11: Somme de Facture_Mensuelle | I11: Somme de Montant_Remise | K11: Type de forfait | L11: Somme de Facture_Mensuelle
B12: 27 | D12: B2B | E12: 5 | H12: 1471.78 | I12: 447.907 | K12: Bloqué 5Go | L12: 400.62
D13: B2C | E13: 22 | K13: Illimité 50Go | L13: 236.03
D14: Total général | E14: 27 | K14: Premium 5G 150Go | L14: 380.57
K15: Pro Monde | L15: 454.56
K16: Total général | L16: 1471.78

Sheet CLIENT
A1: Source.Name | B1: ID_Client | C1: Province_Client | D1: Anciennete_Mois | E1: Type_Forfait | F1: Duree_Cumulee_Panne_Min | G1: Facture_Mensuelle | H1: Plaintes_Service_Client | I1: Type_Client | J1: Panne_Heure | K1: Anciennete_Annee | L1: Remise | M1: Montant_Remise
A2: Clients_Churn_Part_05.xlsx | B2: CLI-00007 | C2: Tanganyika | D2: 110 | E2: Bloqué 5Go | F2: 112 | G2: 98.95 | H2: 5 | I2: =IF(E3="Pro Monde","B2B","B2C") -> B2B | J2: =CLIENT[[#This Row],[Duree_Cumulee_Panne_Min]]/1440 -> 0.077777778 | K2: =CLIENT[[#This Row],[Anciennete_Mois]]/12 -> 9.1666667 | L2: =IF(AND(CLIENT[[#This Row],[Panne_Heure]]>TIME(12,0,0),CLIENT[[#This Row],[Anciennete_Annee]]>5),0.7, IF(OR( AND(CLIENT[[#This Row],[Panne_Heure]]>=TIME(4,0,0),CLIENT[[#This Row],[Panne_Heure]]<=TIME(12,0,0)), AND(CLIENT[[#This Row],[Anciennete_Annee]]<5,CLIENT[[#This Row],[Type_Forfait]]="Premium 5G 150Go") ),0.45, IF(CLIENT[[#This Row],[Type_Client]]="B2B",0.1,0))) -> 0.1 | M2: =CLIENT[[#This Row],[Facture_Mensuelle]]*CLIENT[[#This Row],[Remise]] -> 9.895
A3: Clients_Churn_Part_10.xlsx | B3: CLI-00009 | C3: Kwilu | D3: 105 | E3: Pro Monde | F3: 297 | G3: 84.66 | H3: 2 | I3: =IF(E4="Pro Monde","B2B","B2C") -> B2C | J3: =CLIENT[[#This Row],[Duree_Cumulee_Panne_Min]]/1440 -> 0.20625 | K3: =CLIENT[[#This Row],[Anciennete_Mois]]/12 -> 8.75 | L3: =IF(AND(CLIENT[[#This Row],[Panne_Heure]]>TIME(12,0,0),CLIENT[[#This Row],[Anciennete_Annee]]>5),0.7, IF(OR( AND(CLIENT[[#This Row],[Panne_Heure]]>=TIME(4,0,0),CLIENT[[#This Row],[Panne_Heure]]<=TIME(12,0,0)), AND(CLIENT[[#This Row],[Anciennete_Annee]]<5,CLIENT[[#This Row],[Type_Forfait]]="Premium 5G 150Go") ),0.45, IF(CLIENT[[#This Row],[Type_Client]]="B2B",0.1,0))) -> 0.45 | M3: =CLIENT[[#This Row],[Facture_Mensuelle]]*CLIENT[[#This Row],[Remise]] -> 38.097
A4: Clients_Churn_Part_10.xlsx | B4: CLI-00012 | C4: Kongo-Central | D4: 105 | E4: Illimité 50Go | F4: 172 | G4: 15.88 | H4: 5 | I4: =IF(E5="Pro Monde","B2B","B2C") -> B2C | J4: =CLIENT[[#This Row],[Duree_Cumulee_Panne_Min]]/1440 -> 0.11944444 | K4: =CLIENT[[#This Row],[Anciennete_Mois]]/12 -> 8.75 | L4: =IF(AND(CLIENT[[#This Row],[Panne_Heure]]>TIME(12,0,0),CLIENT[[#This Row],[Anciennete_Annee]]>5),0.7, IF(OR( AND(CLIENT[[#This Row],[Panne_Heure]]>=TIME(4,0,0),CLIENT[[#This Row],[Panne_Heure]]<=TIME(12,0,0)), AND(CLIENT[[#This Row],[Anciennete_Annee]]<5,CLIENT[[#This Row],[Type_Forfait]]="Premium 5G 150Go") ),0.45, IF(CLIENT[[#This Row],[Type_Client]]="B2B",0.1,0))) -> 0 | M4: =CLIENT[[#This Row],[Facture_Mensuelle]]*CLIENT[[#This Row],[Remise]] -> 0
A5: Clients_Churn_Part_03.xlsx | B5: CLI-00017 | C5: Tanganyika | D5: 29 | E5: Illimité 50Go | F5: 124 | G5: 43.83 | H5: 5 | I5: =IF(E6="Pro Monde","B2B","B2C") -> B2C | J5: =CLIENT[[#This Row],[Duree_Cumulee_Panne_Min]]/1440 -> 0.086111111 | K5: =CLIENT[[#This Row],[Anciennete_Mois]]/12 -> 2.4166667 | L5: =IF(AND(CLIENT[[#This Row],[Panne_Heure]]>TIME(12,0,0),CLIENT[[#This Row],[Anciennete_Annee]]>5),0.7, IF(OR( AND(CLIENT[[#This Row],[Panne_Heure]]>=TIME(4,0,0),CLIENT[[#This Row],[Panne_Heure]]<=TIME(12,0,0)), AND(CLIENT[[#This Row],[Anciennete_Annee]]<5,CLIENT[[#This Row],[Type_Forfait]]="Premium 5G 150Go") ),0.45, IF(CLIENT[[#This Row],[Type_Client]]="B2B",0.1,0))) -> 0 | M5: =CLIENT[[#This Row],[Facture_Mensuelle]]*CLIENT[[#This Row],[Remise]] -> 0
A6: Clients_Churn_Part_07.xlsx | B6: CLI-00022 | C6: Haut-Lomami | D6: 77 | E6: Premium 5G 150Go | F6: 488 | G6: 21.17 | H6: 0 | I6: =IF(E7="Pro Monde","B2B","B2C") -> B2B | J6: =CLIENT[[#This Row],[Duree_Cumulee_Panne_Min]]/1440 -> 0.33888889 | K6: =CLIENT[[#This Row],[Anciennete_Mois]]/12 -> 6.4166667 | L6: =IF(AND(CLIENT[[#This Row],[Panne_Heure]]>TIME(12,0,0),CLIENT[[#This Row],[Anciennete_Annee]]>5),0.7, IF(OR( AND(CLIENT[[#This Row],[Panne_Heure]]>=TIME(4,0,0),CLIENT[[#This Row],[Panne_Heure]]<=TIME(12,0,0)), AND(CLIENT[[#This Row],[Anciennete_Annee]]<5,CLIENT[[#This Row],[Type_Forfait]]="Premium 5G 150Go") ),0.45, IF(CLIENT[[#This Row],[Type_Client]]="B2B",0.1,0))) -> 0.45 | M6: =CLIENT[[#This Row],[Facture_Mensuelle]]*CLIENT[[#This Row],[Remise]] -> 9.5265
A7: Clients_Churn_Part_13.xlsx | B7: CLI-00028 | C7: Kwilu | D7: 18 | E7: Pro Monde | F7: 216 | G7: 33.74 | H7: 5 | I7: =IF(E8="Pro Monde","B2B","B2C") -> B2B | J7: =CLIENT[[#This Row],[Duree_Cumulee_Panne_Min]]/1440 -> 0.15 | K7: =CLIENT[[#This Row],[Anciennete_Mois]]/12 -> 1.5 | L7: =IF(AND(CLIENT[[#This Row],[Panne_Heure]]>TIME(12,0,0),CLIENT[[#This Row],[Anciennete_Annee]]>5),0.7, IF(OR( AND(CLIENT[[#This Row],[Panne_Heure]]>=TIME(4,0,0),CLIENT[[#This Row],[Panne_Heure]]<=TIME(12,0,0)), AND(CLIENT[[#This Row],[Anciennete_Annee]]<5,CLIENT[[#This Row],[Type_Forfait]]="Premium 5G 150Go") ),0.45, IF(CLIENT[[#This Row],[Type_Client]]="B2B",0.1,0))) -> 0.1 | M7: =CLIENT[[#This Row],[Facture_Mensuelle]]*CLIENT[[#This Row],[Remise]] -> 3.374
A8: Clients_Churn_Part_06.xlsx | B8: CLI-00029 | C8: Bas-Uele | D8: 119 | E8: Pro Monde | F8: 344 | G8: 10.28 | H8: 0 | I8: =IF(E9="Pro Monde","B2B","B2C") -> B2C | J8: =CLIENT[[#This Row],[Duree_Cumulee_Panne_Min]]/1440 -> 0.23888889 | K8: =CLIENT[[#This Row],[Anciennete_Mois]]/12 -> 9.9166667 | L8: =IF(AND(CLIENT[[#This Row],[Panne_Heure]]>TIME(12,0,0),CLIENT[[#This Row],[Anciennete_Annee]]>5),0.7, IF(OR( AND(CLIENT[[#This Row],[Panne_Heure]]>=TIME(4,0,0),CLIENT[[#This Row],[Panne_Heure]]<=TIME(12,0,0)), AND(CLIENT[[#This Row],[Anciennete_Annee]]<5,CLIENT[[#This Row],[Type_Forfait]]="Premium 5G 150Go") ),0.45, IF(CLIENT[[#This Row],[Type_Client]]="B2B",0.1,0))) -> 0.45 | M8: =CLIENT[[#This Row],[Facture_Mensuelle]]*CLIENT[[#This Row],[Remise]] -> 4.626
A9: Clients_Churn_Part_13.xlsx | B9: CLI-00034 | C9: Kongo-Central | D9: 25 | E9: Bloqué 5Go | F9: 95 | G9: 15.93 | H9: 4 | I9: =IF(E10="Pro Monde","B2B","B2C") -> B2C | J9: =CLIENT[[#This Row],[Duree_Cumulee_Panne_Min]]/1440 -> 0.065972222 | K9: =CLIENT[[#This Row],[Anciennete_Mois]]/12 -> 2.0833333 | L9: =IF(AND(CLIENT[[#This Row],[Panne_Heure]]>TIME(12,0,0),CLIENT[[#This Row],[Anciennete_Annee]]>5),0.7, IF(OR( AND(CLIENT[[#This Row],[Panne_Heure]]>=TIME(4,0,0),CLIENT[[#This Row],[Panne_Heure]]<=TIME(12,0,0)), AND(CLIENT[[#This Row],[Anciennete_Annee]]<5,CLIENT[[#This Row],[Type_Forfait]]="Premium 5G 150Go") ),0.45, IF(CLIENT[[#This Row],[Type_Client]]="B2B",0.1,0))) -> 0 | M9: =CLIENT[[#This Row],[Facture_Mensuelle]]*CLIENT[[#This Row],[Remise]] -> 0
A10: Clients_Churn_Part_13.xlsx | B10: CLI-00037 | C10: Tanganyika | D10: 35 | E10: Premium 5G 150Go | F10: 332 | G10: 11.15 | H10: 0 | I10: =IF(E11="Pro Monde","B2B","B2C") -> B2B | J10: =CLIENT[[#This Row],[Duree_Cumulee_Panne_Min]]/1440 -> 0.23055556 | K10: =CLIENT[[#This Row],[Anciennete_Mois]]/12 -> 2.9166667 | L10: =IF(AND(CLIENT[[#This Row],[Panne_Heure]]>TIME(12,0,0),CLIENT[[#This Row],[Anciennete_Annee]]>5),0.7, IF(OR( AND(CLIENT[[#This Row],[Panne_Heure]]>=TIME(4,0,0),CLIENT[[#This Row],[Panne_Heure]]<=TIME(12,0,0)), AND(CLIENT[[#This Row],[Anciennete_Annee]]<5,CLIENT[[#This Row],[Type_Forfait]]="Premium 5G 150Go") ),0.45, IF(CLIENT[[#This Row],[Type_Client]]="B2B",0.1,0))) -> 0.45 | M10: =CLIENT[[#This Row],[Facture_Mensuelle]]*CLIENT[[#This Row],[Remise]] -> 5.0175
A11: Clients_Churn_Part_15.xlsx | B11: CLI-00039 | C11: Maniema | D11: 119 | E11: Pro Monde | F11: 31 | G11: 21.27 | H11: 5 | I11: =IF(E12="Pro Monde","B2B","B2C") -> B2B | J11: =CLIENT[[#This Row],[Duree_Cumulee_Panne_Min]]/1440 -> 0.021527778 | K11: =CLIENT[[#This Row],[Anciennete_Mois]]/12 -> 9.9166667 | L11: =IF(AND(CLIENT[[#This Row],[Panne_Heure]]>TIME(12,0,0),CLIENT[[#This Row],[Anciennete_Annee]]>5),0.7, IF(OR( AND(CLIENT[[#This Row],[Panne_Heure]]>=TIME(4,0,0),CLIENT[[#This Row],[Panne_Heure]]<=TIME(12,0,0)), AND(CLIENT[[#This Row],[Anciennete_Annee]]<5,CLIENT[[#This Row],[Type_Forfait]]="Premium 5G 150Go") ),0.45, IF(CLIENT[[#This Row],[Type_Client]]="B2B",0.1,0))) -> 0.1 | M11: =CLIENT[[#This Row],[Facture_Mensuelle]]*CLIENT[[#This Row],[Remise]] -> 2.127
A12: Clients_Churn_Part_01.xlsx | B12: CLI-00041 | C12: Ituri | D12: 103 | E12: Pro Monde | F12: 105 | G12: 61.52 | H12: 3 | I12: =IF(E13="Pro Monde","B2B","B2C") -> B2B | J12: =CLIENT[[#This Row],[Duree_Cumulee_Panne_Min]]/1440 -> 0.072916667 | K12: =CLIENT[[#This Row],[Anciennete_Mois]]/12 -> 8.5833333 | L12: =IF(AND(CLIENT[[#This Row],[Panne_Heure]]>TIME(12,0,0),CLIENT[[#This Row],[Anciennete_Annee]]>5),0.7, IF(OR( AND(CLIENT[[#This Row],[Panne_Heure]]>=TIME(4,0,0),CLIENT[[#This Row],[Panne_Heure]]<=TIME(12,0,0)), AND(CLIENT[[#This Row],[Anciennete_Annee]]<5,CLIENT[[#This Row],[Type_Forfait]]="Premium 5G 150Go") ),0.45, IF(CLIENT[[#This Row],[Type_Client]]="B2B",0.1,0))) -> 0.1 | M12: =CLIENT[[#This Row],[Facture_Mensuelle]]*CLIENT[[#This Row],[Remise]] -> 6.152
A13: Clients_Churn_Part_06.xlsx | B13: CLI-00043 | C13: Nord-Kivu | D13: 118 | E13: Pro Monde | F13: 132 | G13: 40.88 | H13: 4 | I13: =IF(E14="Pro Monde","B2B","B2C") -> B2C | J13: =CLIENT[[#This Row],[Duree_Cumulee_Panne_Min]]/1440 -> 0.091666667 | K13: =CLIENT[[#This Row],[Anciennete_Mois]]/12 -> 9.8333333 | L13: =IF(AND(CLIENT[[#This Row],[Panne_Heure]]>TIME(12,0,0),CLIENT[[#This Row],[Anciennete_Annee]]>5),0.7, IF(OR( AND(CLIENT[[#This Row],[Panne_Heure]]>=TIME(4,0,0),CLIENT[[#This Row],[Panne_Heure]]<=TIME(12,0,0)), AND(CLIENT[[#This Row],[Anciennete_Annee]]<5,CLIENT[[#This Row],[Type_Forfait]]="Premium 5G 150Go") ),0.45, IF(CLIENT[[#This Row],[Type_Client]]="B2B",0.1,0))) -> 0 | M13: =CLIENT[[#This Row],[Facture_Mensuelle]]*CLIENT[[#This Row],[Remise]] -> 0
... A679: Clients_Churn_Part_09.xlsx | B679: CLI-01999 | C679: Sud-Ubangi | D679: 47 | E679: Pro Monde | F679: 149 | G679: 28.35 | H679: 1 | I679: =IF(E680="Pro Monde","B2B","B2C") -> B2C | J679: =CLIENT[[#This Row],[Duree_Cumulee_Panne_Min]]/1440 -> 0.10347222 | K679: =CLIENT[[#This Row],[Anciennete_Mois]]/12 -> 3.9166667 | L679: =IF(AND(CLIENT[[#This Row],[Panne_Heure]]>TIME(12,0,0),CLIENT[[#This Row],[Anciennete_Annee]]>5),0.7, IF(OR( AND(CLIENT[[#This Row],[Panne_Heure]]>=TIME(4,0,0),CLIENT[[#This Row],[Panne_Heure]]<=TIME(12,0,0)), AND(CLIENT[[#This Row],[Anciennete_Annee]]<5,CLIENT[[#This Row],[Type_Forfait]]="Premium 5G 150Go") ),0.45, IF(CLIENT[[#This Row],[Type_Client]]="B2B",0.1,0))) -> 0 | M679: =CLIENT[[#This Row],[Facture_Mensuelle]]*CLIENT[[#This Row],[Remise]] -> 0

Sheet ANT_Non_Loc
A1: Source.Name | B1: Date_Heure_Panne | C1: Cell_ID | D1: Duree_Panne_Min | E1: Statut_Resolution | F1: Province_RDC | G1: Latitude | H1: longitude | I1: Technologie | J1: Equipementier
A2: Logs_Reseau_Part_01.xlsx | B2: 45208.301 | C2: ANT-0004 | D2: 38 | E2: Résolu | F2: #N/A | G2: #N/A | H2: #N/A | I2: #N/A | J2: #N/A
A3: Logs_Reseau_Part_02.xlsx | B3: 45226.003 | C3: ANT-0004 | D3: 111 | E3: Résolu | F3: #N/A | G3: #N/A | H3: #N/A | I3: #N/A | J3: #N/A
A4: Logs_Reseau_Part_13.xlsx | B4: 45216.951 | C4: ANT-0004 | D4: 12 | E4: Résolu | F4: #N/A | G4: #N/A | H4: #N/A | I4: #N/A | J4: #N/A
A5: Logs_Reseau_Part_14.xlsx | B5: 45222.56 | C5: ANT-0013 | D5: 26 | E5: En Cours | F5: #N/A | G5: #N/A | H5: #N/A | I5: #N/A | J5: #N/A
A6: Logs_Reseau_Part_17.xlsx | B6: 45213.922 | C6: ANT-0013 | D6: 40 | E6: Résolu | F6: #N/A | G6: #N/A | H6: #N/A | I6: #N/A | J6: #N/A
A7: Logs_Reseau_Part_04.xlsx | B7: 45219.99 | C7: ANT-0018 | D7: 36 | E7: Résolu | F7: #N/A | G7: #N/A | H7: #N/A | I7: #N/A | J7: #N/A
A8: Logs_Reseau_Part_14.xlsx | B8: 45204.392 | C8: ANT-0018 | D8: 98 | E8: En Cours | F8: #N/A | G8: #N/A | H8: #N/A | I8: #N/A | J8: #N/A
A9: Logs_Reseau_Part_14.xlsx | B9: 45230.566 | C9: ANT-0018 | D9: 74 | E9: Résolu | F9: #N/A | G9: #N/A | H9: #N/A | I9: #N/A | J9: #N/A
A10: Logs_Reseau_Part_23.xlsx | B10: 45213.963 | C10: ANT-0019 | D10: 25 | E10: Non Résolu | F10: #N/A | G10: #N/A | H10: #N/A | I10: #N/A | J10: #N/A
A11: Logs_Reseau_Part_19.xlsx | B11: 45217.64 | C11: ANT-0021 | D11: 113 | E11: En Cours | F11: #N/A | G11: #N/A | H11: #N/A | I11: #N/A | J11: #N/A
A12: Logs_Reseau_Part_22.xlsx | B12: 45220.093 | C12: ANT-0021 | D12: 48 | E12: Résolu | F12: #N/A | G12: #N/A | H12: #N/A | I12: #N/A | J12: #N/A
A13: Logs_Reseau_Part_08.xlsx | B13: 45204.896 | C13: ANT-0022 | D13: 42 | E13: Non Résolu | F13: #N/A | G13: #N/A | H13: #N/A | I13: #N/A | J13: #N/A
... A146: Logs_Reseau_Part_06.xlsx | B146: 45229.756 | C146: ANT-0280 | D146: 82 | E146: En Cours | F146: #N/A | G146: #N/A | H146: #N/A | I146: #N/A | J146: #N/A
A147: Logs_Reseau_Part_24.xlsx | B147: 17/10/2023 05:44 | C147: ANT-0286 | D147: 11 | E147: Résolu | F147: #N/A | G147: #N/A | H147: #N/A | I147: #N/A | J147: #N/A
A148: Logs_Reseau_Part_09.xlsx | B148: 45222.603 | C148: ANT-0289 | D148: 53 | E148: Non Résolu | F148: #N/A | G148: #N/A | H148: #N/A | I148: #N/A | J148: #N/A
A149: Logs_Reseau_Part_21.xlsx | B149: 45223.568 | C149: ANT-0290 | D149: 21 | E149: Résolu | F149: #N/A | G149: #N/A | H149: #N/A | I149: #N/A | J149: #N/A
A150: Logs_Reseau_Part_22.xlsx | B150: 45223.693 | C150: ANT-0290 | D150: 18 | E150: Non Résolu | F150: #N/A | G150: #N/A | H150: #N/A | I150: #N/A | J150: #N/A
A151: Logs_Reseau_Part_16.xlsx | B151: 45216.182 | C151: ANT-0296 | D151: 86 | E151: Non Résolu | F151: #N/A | G151: #N/A | H151: #N/A | I151: #N/A | J151: #N/A
A152: Logs_Reseau_Part_15.xlsx | B152: 45211.712 | C152: ANT-0299 | D152: 82 | E152: Non Résolu | F152: #N/A | G152: #N/A | H152: #N/A | I152: #N/A | J152: #N/A
A153: Logs_Reseau_Part_18.xlsx | B153: 45202.728 | C153: ANT-0299 | D153: 18 | E153: Résolu | F153: #N/A | G153: #N/A | H153: #N/A | I153: #N/A | J153: #N/A
A154: Logs_Reseau_Part_06.xlsx | B154: 45202.319 | C154: ANT-0303 | D154: 115 | E154: Non Résolu | F154: #N/A | G154: #N/A | H154: #N/A | I154: #N/A | J154: #N/A
A155: Logs_Reseau_Part_17.xlsx | B155: 45203.228 | C155: ANT-0303 | D155: 61 | E155: Non Résolu | F155: #N/A | G155: #N/A | H155: #N/A | I155: #N/A | J155: #N/A
A156: Logs_Reseau_Part_16.xlsx | B156: 45214.799 | C156: ANT-0305 | D156: 67 | E156: Résolu | F156: #N/A | G156: #N/A | H156: #N/A | I156: #N/A | J156: #N/A
A157: Logs_Reseau_Part_01.xlsx | B157: 45210.128 | C157: ANT-0306 | D157: 115 | E157: Résolu | F157: #N/A | G157: #N/A | H157: #N/A | I157: #N/A | J157: #N/A
A158: Logs_Reseau_Part_13.xlsx | B158: 45219.301 | C158: ANT-0306 | D158: 65 | E158: Résolu | F158: #N/A | G158: #N/A | H158: #N/A | I158: #N/A | J158: #N/A
A159: Logs_Reseau_Part_21.xlsx | B159: 45220.092 | C159: ANT-0306 | D159: 87 | E159: Non Résolu | F159: #N/A | G159: #N/A | H159: #N/A | I159: #N/A | J159: #N/A
... A475: Logs_Reseau_Part_01.xlsx | B475: 45213.428 | C475: ANT-0892 | D475: 101 | E475: Non Résolu | F475: #N/A | G475: #N/A | H475: #N/A | I475: #N/A | J475: #N/A
A476: Logs_Reseau_Part_08.xlsx | B476: 22/10/2023 02:17 | C476: ANT-0892 | D476: 10 | E476: Non Résolu | F476: #N/A | G476: #N/A | H476: #N/A | I476: #N/A | J476: #N/A
A477: Logs_Reseau_Part_09.xlsx | B477: 45220.453 | C477: ANT-0896 | D477: 35 | E477: Non Résolu | F477: #N/A | G477: #N/A | H477: #N/A | I477: #N/A | J477: #N/A
A478: Logs_Reseau_Part_16.xlsx | B478: 45226.906 | C478: ANT-0896 | D478: 26 | E478: Non Résolu | F478: #N/A | G478: #N/A | H478: #N/A | I478: #N/A | J478: #N/A
A479: Logs_Reseau_Part_01.xlsx | B479: 45217.109 | C479: ANT-0897 | D479: 59 | E479: Résolu | F479: #N/A | G479: #N/A | H479: #N/A | I479: #N/A | J479: #N/A
A480: Logs_Reseau_Part_13.xlsx | B480: 45222.772 | C480: ANT-0897 | D480: 53 | E480: En Cours | F480: #N/A | G480: #N/A | H480: #N/A | I480: #N/A | J480: #N/A
A481: Logs_Reseau_Part_17.xlsx | B481: 45217.509 | C481: ANT-0897 | D481: 49 | E481: Résolu | F481: #N/A | G481: #N/A | H481: #N/A | I481: #N/A | J481: #N/A
A482: Logs_Reseau_Part_06.xlsx | B482: 45204.315 | C482: ANT-0898 | D482: 120 | E482: Non Résolu | F482: #N/A | G482: #N/A | H482: #N/A | I482: #N/A | J482: #N/A
A483: Logs_Reseau_Part_11.xlsx | B483: 45208.194 | C483: ANT-0901 | D483: 98 | E483: Non Résolu | F483: #N/A | G483: #N/A | H483: #N/A | I483: #N/A | J483: #N/A
A484: Logs_Reseau_Part_19.xlsx | B484: 45211.29 | C484: ANT-0903 | D484: 73 | E484: En Cours | F484: #N/A | G484: #N/A | H484: #N/A | I484: #N/A | J484: #N/A
A485: Logs_Reseau_Part_20.xlsx | B485: 45210.247 | C485: ANT-0903 | D485: 74 | E485: Résolu | F485: #N/A | G485: #N/A | H485: #N/A | I485: #N/A | J485: #N/A
A486: Logs_Reseau_Part_02.xlsx | B486: 45227.211 | C486: ANT-0905 | D486: 38 | E486: Résolu | F486: #N/A | G486: #N/A | H486: #N/A | I486: #N/A | J486: #N/A
A487: Logs_Reseau_Part_17.xlsx | B487: 45226.163 | C487: ANT-0911 | D487: 36 | E487: Non Résolu | F487: #N/A | G487: #N/A | H487: #N/A | I487: #N/A | J487: #N/A
...

Sheet LOGS
A1: Source.Name | B1: Date_Heure_Panne | C1: Cell_ID | D1: Duree_Panne_Min | E1: Statut_Resolution
A2: Logs_Reseau_Part_01.xlsx | B2: 45211.279 | C2: ANT-0001 | D2: 75 | E2: Résolu
A3: Logs_Reseau_Part_19.xlsx | B3: 45205.014 | C3: ANT-0001 | D3: 35 | E3: Non Résolu
A4: Logs_Reseau_Part_23.xlsx | B4: 45203.517 | C4: ANT-0001 | D4: 26 | E4: Résolu
A5: Logs_Reseau_Part_05.xlsx | B5: 45224.568 | C5: ANT-0002 | D5: 27 | E5: Résolu
A6: Logs_Reseau_Part_01.xlsx | B6: 45208.301 | C6: ANT-0004 | D6: 38 | E6: Résolu
A7: Logs_Reseau_Part_02.xlsx | B7: 45226.003 | C7: ANT-0004 | D7: 111 | E7: Résolu
A8: Logs_Reseau_Part_13.xlsx | B8: 45216.951 | C8: ANT-0004 | D8: 12 | E8: Résolu
A9: Logs_Reseau_Part_12.xlsx | B9: 45230.868 | C9: ANT-0006 | D9: 103 | E9: En Cours
A10: Logs_Reseau_Part_24.xlsx | B10: 45230.429 | C10: ANT-0006 | D10: 11 | E10: En Cours
A11: Logs_Reseau_Part_14.xlsx | B11: 45221.566 | C11: ANT-0007 | D11: 87 | E11: Non Résolu
A12: Logs_Reseau_Part_21.xlsx | B12: 45222.501 | C12: ANT-0008 | D12: 39 | E12: Résolu
A13: Logs_Reseau_Part_02.xlsx | B13: 45223.419 | C13: ANT-0010 | D13: 89 | E13: Résolu
... A1069: Logs_Reseau_Part_18.xlsx | B1069: 45224.165 | C1069: ANT-0998 | D1069: 57 | E1069: Non Résolu

Sheet REGISTRE
A1: Source.Name | B1: ID_Antenne | C1: Province_RDC | D1: Latitude | E1: Longitude | F1: Technologie | G1: Equipementier
A2: Registre_Maintenance_Part_08.xlsx | B2: ANT-0001 | C2: Nord-Ubangi | D2: -8.143791 | E2: 28.946161 | F2: 4G | G2: ZTE
A3: Registre_Maintenance_Part_06.xlsx | B3: ANT-0002 | C3: Mai-Ndombe | D3: -10.442425 | E3: 23.243632 | F3: 4G | G3: Nokia
A4: Registre_Maintenance_Part_09.xlsx | B4: ANT-0005 | C4: Equateur | D4: -3.544581 | E4: 14.776605 | F4: 4G | G4: Nokia
A5: Registre_Maintenance_Part_06.xlsx | B5: ANT-0006 | C5: Bas-Uele | D5: -2.853287 | E5: 22.117896 | F5: 5G | G5: Huawei
A6: Registre_Maintenance_Part_03.xlsx | B6: ANT-0007 | C6: Tshopo | D6: 4.777735 | E6: 16.392204 | F6: 5G | G6: ZTE
A7: Registre_Maintenance_Part_06.xlsx | B7: ANT-0008 | C7: Haut-Lomami | D7: -11.89448 | E7: 19.216215 | F7: 3G | G7: ZTE
A8: Registre_Maintenance_Part_09.xlsx | B8: ANT-0010 | C8: Haut-Katanga | D8: 4.471256 | E8: 27.107028 | F8: 3G | G8: Ericsson
A9: Registre_Maintenance_Part_02.xlsx | B9: ANT-0011 | C9: Mai-Ndombe | D9: -1.607639 | E9: 17.003636 | F9: 4G | G9: Ericsson
A10: Registre_Maintenance_Part_08.xlsx | B10: ANT-0016 | C10: Kongo-Central | D10: 2.983602 | E10: 21.893065 | F10: 5G | G10: Nokia
A11: Registre_Maintenance_Part_05.xlsx | B11: ANT-0017 | C11: Sankuru | D11: -3.419035 | E11: 29.018316 | F11: 5G | G11: Ericsson
A12: Registre_Maintenance_Part_01.xlsx | B12: ANT-0020 | C12: Kasaï | D12: -10.059846 | E12: 14.375758 | F12: 4G | G12: Huawei
A13: Registre_Maintenance_Part_04.xlsx | B13: ANT-0023 | C13: Haut-Lomami | D13: -9.780186 | E13: 16.64955 | F13: 5G | G13: Ericsson
... A499: Registre_Maintenance_Part_05.xlsx | B499: ANT-1000 | C499: Mai-Ndombe | D499: 2.729824 | E499: 12.958664 | F499: 3G | G499: ZTE

Sheet TCD_Logs_Registre
B8: SOUS CATEGORIE TECHNOLOGIE | E8: EQUIPEMENTIER PAR TECHNOLOGIE | H8: MOYENNE D'ABONNEES IMPACTEES | L8: LES ANTENNES & EQUIPEMENTIERS LES PLUS TOUCHES
B11: Technologie | C11: Antenne | E11: Equipementier par technologie | F11: Antenne | H11: Type de Statut Antenne | I11: Nombre de Statut Antenne | J11: Moyenne | L11: Technologie et Equipementier | M11: Nombre de Statut_Resolution
B12: 3G | C12: 3 | E12: Ericsson | H12: En Cours | I12: 7 | J12: 0.26923077 | L12: Ericsson
B13: 4G | C13: 5 | E13: 5G | F13: 1 | H13: Non Résolu | I13: 5 | J13: 0.19230769 | L13: 3G | M13: 41
B14: 5G | C14: 8 | E14: Huawei | H14: Total général | I14: 12 | J14: 0.46153846 | L14: 4G | M14: 55
B15: Total général | C15: 16 | E15: 3G | F15: 1 | L15: 5G | M15: 53
E16: 4G | F16: 3 | L16: Huawei
E17: 5G | F17: 5 | L17: 3G | M17: 35
E18: Nokia | L18: 4G | M18: 70
E19: 5G | F19: 2 | L19: 5G | M19: 44
E20: ZTE | L20: Nokia
E21: 3G | F21: 2 | L21: 3G | M21: 45
E22: 4G | F22: 2 | L22: 4G | M22: 32
E23: Total général | F23: 16 | L23: 5G | M23: 39
L24: ZTE
L25: 3G | M25: 46
L26: 4G | M26: 28
L27: 5G | M27: 59
L28: Total général | M28: 547
